<?xml version="1.0"?>

<robot name="spatial6r" xmlns:xacro="http://www.ros.org/wiki/xacro">
	<xacro:property name="robot_params" value="${load_yaml('../launch/init_config.yaml')}" />
	<xacro:property name="link_lengths" value="${robot_params['link_lengths']}" />
	<xacro:property name="link1_length" value="${link_lengths['l1']}" />
	<xacro:property name="link2_length" value="${link_lengths['l2']}" />
	<xacro:property name="link3_length" value="${link_lengths['l3']}" />
	<xacro:property name="link4_length" value="${link_lengths['l4']}" />
	<xacro:property name="link5_length" value="${link_lengths['l5']}" />
	<xacro:property name="link6_length" value="${link_lengths['l6']}" />
	
	<material name="mat_base">
		<color rgba="0.13 0.18 0.24 0.8"/>
	</material>
	<material name="mat_joint">
		<color rgba="0.10 0.32 0.46 0.8"/>
	</material>
	<material name="mat_link1">
		<color rgba="0.48 0.14 0.11 0.7"/>
	</material>

	<material name="mat_link2">
	  <color rgba="0.10 0.44 0.24 0.7"/>
	</material>
	
	<material name="mat_link3">
	  <color rgba="0.13 0.18 0.24 0.7"/>
	</material>
	
	<material name="mat_link4">
	  <color rgba="0.05 0.60 0.24 0.7"/>
	</material>
	
	<material name="mat_link5">
	  <color rgba="0.13 0.18 0.5 0.7"/>
	</material>
	
	<material name="mat_link6">
	  <color rgba="0.10 0.58 0.05 0.7"/>
	</material>
	
	<link name="base_link">
		<visual>
			<geometry>
				<cylinder length = "0.2" radius = "0.10" />
			</geometry>
			<material name="mat_base"/>
			<origin rpy="0 0 0" xyz="0 0 -0.1"/>
		</visual>
	</link>

	<link name="link1">
		<visual>
			<geometry>
				<cylinder length = "${link1_length}" radius = "0.1" />
			</geometry>
			<material name="mat_link1"/>
			<origin rpy="0 0 0" xyz="0 0 ${link1_length/2}"/>
		</visual>
	</link>

	<joint name="joint1" type="continuous">
		<axis xyz="0 0 1" />
		<parent link="base_link"/>
		<child link="link1"/>
	</joint>

	<link name="link2">
		<visual>
			<geometry>
				<box size="${link2_length} 0.1 0.1"/>
			</geometry>
			<material name="mat_link2"/>
			<origin rpy="0 0 0" xyz="${link2_length/2} 0 0"/>
		</visual>
	</link>

	<joint name="joint2" type="continuous">
		<axis xyz="0 -1 0" />
		<parent link="link1"/>
		<child link="link2"/>
		<origin rpy="0 0 0" xyz="0 0 ${link1_length}"/>
	</joint>

	<link name="link3">
		<visual>
			<geometry>
				<box size="${link3_length} 0.1 0.1"/>
			</geometry>
			<material name="mat_link3"/>
			<origin rpy="0 0 0" xyz="${link3_length/2} 0 0"/>
		</visual>
	</link>

	<joint name="joint3" type="continuous">
		<axis xyz="0 -1 0" />
		<parent link="link2"/>
		<child link="link3"/>
		<origin rpy="0 0 0" xyz="${link2_length} 0 0"/>
	</joint>

	<link name="link4">
	  <visual>
	    <geometry>
	      <box size = "${link4_length} 0.10 0.10"/>
	    </geometry>
	    <material name="mat_link4"/>
	    <origin rpy="0 0 0" xyz="${link4_length/2} 0 0"/>
	  </visual>
	</link>

	<joint name="joint4" type="continuous">
	  <axis xyz="0 0 1" />
	  <parent link="link3"/>
	  <child link="link4"/>
	  <origin rpy="0 0 0" xyz="${link3_length} 0 0"/>
	</joint>

	<link name="link5">
	  <visual>
	    <geometry>
	      <box size = "${link5_length} 0.10 0.10"/>
	    </geometry>
	    <material name="mat_link4"/>
	    <origin rpy="0 0 0" xyz="${link5_length/2} 0 0"/>
	  </visual>
	</link>

	<joint name="joint5" type="continuous">
	  <axis xyz="0 1 0" />
	  <parent link="link4"/>
	  <child link="link5"/>
	  <origin rpy="0 0 0" xyz="${link4_length} 0 0"/>
	</joint>

	<link name="link6">
	  <visual>
	    <geometry>
	      <box size = "${link6_length} 0.10 0.10"/>
	    </geometry>
	    <material name="mat_link6"/>
	    <origin rpy="0 0 0" xyz="${link6_length/2} 0 0"/>
	  </visual>
	</link>

	<joint name="joint6" type="continuous">
	  <axis xyz="1 0 0" />
	  <parent link="link5"/>
	  <child link="link6"/>
	  <origin rpy="0 0 0" xyz="${link5_length} 0 0"/>
	</joint> 
	
	<link name="endEffector">
	  <visual>
	    <geometry>
	      <box size = "0.4 0.4 0.2"/>
	    </geometry>
	    <material name="mat_base"/>
	    <origin rpy="0 0 0" xyz="0 0 0"/>
	  </visual>
	</link>

	<joint name="endEff" type="fixed">
		<parent link="link6"/>
		<child link="endEffector"/>
		<origin xyz="0 0 0"/>
	</joint>

</robot>
